<?xml version="1.0" encoding="UTF-8"?>
<testsuites name="Mocha Tests" time="28.333" tests="2" failures="1">
  <testsuite name="Root Suite" timestamp="2020-03-28T19:30:50" tests="0" file="cypress/integration/apps/lims/LM22.js" failures="0" time="0">
  </testsuite>
  <testsuite name="22 - I should be able to save changes to the Protocols" timestamp="2020-03-28T19:30:50" tests="2" failures="1" time="28.333">
    <testcase name="22 - I should be able to save changes to the Protocols LM-22-1 Should be able to save changes to protocols" time="16.711" classname="LM-22-1 Should be able to save changes to protocols">
    </testcase>
    <testcase name="22 - I should be able to save changes to the Protocols LM-22-2 Should be able to save and continue" time="5.811" classname="LM-22-2 Should be able to save and continue">
    </testcase>
    <testcase name="22 - I should be able to save changes to the Protocols &quot;after all&quot; hook for &quot;LM-22-2 Should be able to save and continue&quot;" time="5.811" classname="&quot;after all&quot; hook for &quot;LM-22-2 Should be able to save and continue&quot;">
      <failure message="cy.exec(&apos;esp  -P 8080 -H 127.0.0.1 -u admin@localhost -p admin seed -f -d cypress/fixtures/apps/lims/LM22seed.yml&apos;) failed because the command exited with a non-zero code.

Pass {failOnNonZeroExit: false} to ignore exit code failures.

Information about the failure:
Code: 1

Stderr:
INFO:root:2020-03-28 14:31:15,485:Saving data in Experiment LM22-1 for Protocol: LM22a.
INFO:root:2020-03-28 14:31:16,760:Saving data in Experiment LM22-1 for Protocol: LM22b.
Traceback (most recen...

Because this error occurred during a &apos;after all&apos; hook we are skipping the remaining tests in the current suite: &apos;22 - I should be able to sa...&apos;" type="CypressError"><![CDATA[CypressError: cy.exec('esp  -P 8080 -H 127.0.0.1 -u admin@localhost -p admin seed -f -d cypress/fixtures/apps/lims/LM22seed.yml') failed because the command exited with a non-zero code.

Pass {failOnNonZeroExit: false} to ignore exit code failures.

Information about the failure:
Code: 1

Stderr:
INFO:root:2020-03-28 14:31:15,485:Saving data in Experiment LM22-1 for Protocol: LM22a.
INFO:root:2020-03-28 14:31:16,760:Saving data in Experiment LM22-1 for Protocol: LM22b.
Traceback (most recen...

Because this error occurred during a 'after all' hook we are skipping the remaining tests in the current suite: '22 - I should be able to sa...'
    at cypressErr (http://127.0.0.1:8080/__cypress/runner/cypress_runner.js:138036:9)
    at throwErr (http://127.0.0.1:8080/__cypress/runner/cypress_runner.js:137969:11)
    at Object.throwErrByPath (http://127.0.0.1:8080/__cypress/runner/cypress_runner.js:138017:3)
    at http://127.0.0.1:8080/__cypress/runner/cypress_runner.js:125593:26
    at tryCatcher (http://127.0.0.1:8080/__cypress/runner/cypress_runner.js:164895:23)
    at Promise._settlePromiseFromHandler (http://127.0.0.1:8080/__cypress/runner/cypress_runner.js:162831:31)
    at Promise._settlePromise (http://127.0.0.1:8080/__cypress/runner/cypress_runner.js:162888:18)
    at Promise._settlePromise0 (http://127.0.0.1:8080/__cypress/runner/cypress_runner.js:162933:10)
    at Promise._settlePromises (http://127.0.0.1:8080/__cypress/runner/cypress_runner.js:163012:18)
    at Async../node_modules/bluebird/js/release/async.js.Async._drainQueue (http://127.0.0.1:8080/__cypress/runner/cypress_runner.js:159620:16)
    at Async../node_modules/bluebird/js/release/async.js.Async._drainQueues (http://127.0.0.1:8080/__cypress/runner/cypress_runner.js:159630:10)
    at Async.drainQueues (http://127.0.0.1:8080/__cypress/runner/cypress_runner.js:159504:14)]]></failure>
    </testcase>
  </testsuite>
</testsuites>