<?xml version="1.0" encoding="UTF-8"?>
<testsuites name="Mocha Tests" time="18.943" tests="2" failures="1">
  <testsuite name="Root Suite" timestamp="2020-03-28T19:25:41" tests="0" file="cypress/integration/apps/lims/LM04.js" failures="0" time="0">
  </testsuite>
  <testsuite name="4 - I should NOT be able to archive a worksheet that has experiments in it" timestamp="2020-03-28T19:25:41" tests="2" failures="1" time="18.943">
    <testcase name="4 - I should NOT be able to archive a worksheet that has experiments in it LM-4-1 Should NOT be able to archive a worksheet with experiments (List)" time="13.135" classname="LM-4-1 Should NOT be able to archive a worksheet with experiments (List)">
    </testcase>
    <testcase name="4 - I should NOT be able to archive a worksheet that has experiments in it LM-4-2 Should NOT be able to archive a worksheet with experiment (Cards)" time="2.904" classname="LM-4-2 Should NOT be able to archive a worksheet with experiment (Cards)">
    </testcase>
    <testcase name="4 - I should NOT be able to archive a worksheet that has experiments in it &quot;after all&quot; hook for &quot;LM-4-2 Should NOT be able to archive a worksheet with experiment (Cards)&quot;" time="2.904" classname="&quot;after all&quot; hook for &quot;LM-4-2 Should NOT be able to archive a worksheet with experiment (Cards)&quot;">
      <failure message="cy.exec(&apos;esp  -P 8080 -H 127.0.0.1 -u admin@localhost -p admin seed -f -d cypress/fixtures/apps/lims/LM04seed.yml&apos;) failed because the command exited with a non-zero code.

Pass {failOnNonZeroExit: false} to ignore exit code failures.

Information about the failure:
Code: 1

Stderr:
INFO:root:2020-03-28 14:25:59,269:Saving data in Experiment LM4list for Protocol: Simple Protocol.
Traceback (most recent call last):
  File &quot;/Users/cj/bitrepos/esp/develop/bin/.venv/bin/esp&quot;, line...

Because this error occurred during a &apos;after all&apos; hook we are skipping the remaining tests in the current suite: &apos;4 - I should NOT be able to...&apos;" type="CypressError"><![CDATA[CypressError: cy.exec('esp  -P 8080 -H 127.0.0.1 -u admin@localhost -p admin seed -f -d cypress/fixtures/apps/lims/LM04seed.yml') failed because the command exited with a non-zero code.

Pass {failOnNonZeroExit: false} to ignore exit code failures.

Information about the failure:
Code: 1

Stderr:
INFO:root:2020-03-28 14:25:59,269:Saving data in Experiment LM4list for Protocol: Simple Protocol.
Traceback (most recent call last):
  File "/Users/cj/bitrepos/esp/develop/bin/.venv/bin/esp", line...

Because this error occurred during a 'after all' hook we are skipping the remaining tests in the current suite: '4 - I should NOT be able to...'
    at cypressErr (http://127.0.0.1:8080/__cypress/runner/cypress_runner.js:138036:9)
    at throwErr (http://127.0.0.1:8080/__cypress/runner/cypress_runner.js:137969:11)
    at Object.throwErrByPath (http://127.0.0.1:8080/__cypress/runner/cypress_runner.js:138017:3)
    at http://127.0.0.1:8080/__cypress/runner/cypress_runner.js:125593:26
    at tryCatcher (http://127.0.0.1:8080/__cypress/runner/cypress_runner.js:164895:23)
    at Promise._settlePromiseFromHandler (http://127.0.0.1:8080/__cypress/runner/cypress_runner.js:162831:31)
    at Promise._settlePromise (http://127.0.0.1:8080/__cypress/runner/cypress_runner.js:162888:18)
    at Promise._settlePromise0 (http://127.0.0.1:8080/__cypress/runner/cypress_runner.js:162933:10)
    at Promise._settlePromises (http://127.0.0.1:8080/__cypress/runner/cypress_runner.js:163012:18)
    at Async../node_modules/bluebird/js/release/async.js.Async._drainQueue (http://127.0.0.1:8080/__cypress/runner/cypress_runner.js:159620:16)
    at Async../node_modules/bluebird/js/release/async.js.Async._drainQueues (http://127.0.0.1:8080/__cypress/runner/cypress_runner.js:159630:10)
    at Async.drainQueues (http://127.0.0.1:8080/__cypress/runner/cypress_runner.js:159504:14)]]></failure>
    </testcase>
  </testsuite>
</testsuites>