<?xml version="1.0" encoding="UTF-8"?>
<testsuites name="Mocha Tests" time="24.153" tests="2" failures="1">
  <testsuite name="Root Suite" timestamp="2020-03-28T17:26:11" tests="0" file="cypress/integration/apps/expressions/EX01.js" failures="0" time="0">
  </testsuite>
  <testsuite name="1 - I should be able to use the Expression API" timestamp="2020-03-28T17:26:11" tests="2" failures="1" time="24.153">
    <testcase name="1 - I should be able to use the Expression API EX-1-1 Should use python addition expression" time="13.903" classname="EX-1-1 Should use python addition expression">
    </testcase>
    <testcase name="1 - I should be able to use the Expression API EX-1-2 Should use if/else expression" time="5.125" classname="EX-1-2 Should use if/else expression">
    </testcase>
    <testcase name="1 - I should be able to use the Expression API &quot;after all&quot; hook for &quot;EX-1-2 Should use if/else expression&quot;" time="5.125" classname="&quot;after all&quot; hook for &quot;EX-1-2 Should use if/else expression&quot;">
      <failure message="cy.exec(&apos;esp  -P 8080 -H 127.0.0.1 -u admin@localhost -p admin seed -f -d cypress/fixtures/apps/expressions/EX01seed.yml&apos;) failed because the command exited with a non-zero code.

Pass {failOnNonZeroExit: false} to ignore exit code failures.

Information about the failure:
Code: 1

Stderr:
INFO:root:2020-03-28 12:26:32,612:Saving data in Experiment EX1 for Protocol: EX1 standard.
Traceback (most recent call last):
  File &quot;/Users/cj/bitrepos/esp/develop/bin/.venv/bin/esp&quot;, line 11, in...

Because this error occurred during a &apos;after all&apos; hook we are skipping the remaining tests in the current suite: &apos;1 - I should be able to use...&apos;" type="CypressError"><![CDATA[CypressError: cy.exec('esp  -P 8080 -H 127.0.0.1 -u admin@localhost -p admin seed -f -d cypress/fixtures/apps/expressions/EX01seed.yml') failed because the command exited with a non-zero code.

Pass {failOnNonZeroExit: false} to ignore exit code failures.

Information about the failure:
Code: 1

Stderr:
INFO:root:2020-03-28 12:26:32,612:Saving data in Experiment EX1 for Protocol: EX1 standard.
Traceback (most recent call last):
  File "/Users/cj/bitrepos/esp/develop/bin/.venv/bin/esp", line 11, in...

Because this error occurred during a 'after all' hook we are skipping the remaining tests in the current suite: '1 - I should be able to use...'
    at cypressErr (http://127.0.0.1:8080/__cypress/runner/cypress_runner.js:138036:9)
    at throwErr (http://127.0.0.1:8080/__cypress/runner/cypress_runner.js:137969:11)
    at Object.throwErrByPath (http://127.0.0.1:8080/__cypress/runner/cypress_runner.js:138017:3)
    at http://127.0.0.1:8080/__cypress/runner/cypress_runner.js:125593:26
    at tryCatcher (http://127.0.0.1:8080/__cypress/runner/cypress_runner.js:164895:23)
    at Promise._settlePromiseFromHandler (http://127.0.0.1:8080/__cypress/runner/cypress_runner.js:162831:31)
    at Promise._settlePromise (http://127.0.0.1:8080/__cypress/runner/cypress_runner.js:162888:18)
    at Promise._settlePromise0 (http://127.0.0.1:8080/__cypress/runner/cypress_runner.js:162933:10)
    at Promise._settlePromises (http://127.0.0.1:8080/__cypress/runner/cypress_runner.js:163012:18)
    at Async../node_modules/bluebird/js/release/async.js.Async._drainQueue (http://127.0.0.1:8080/__cypress/runner/cypress_runner.js:159620:16)
    at Async../node_modules/bluebird/js/release/async.js.Async._drainQueues (http://127.0.0.1:8080/__cypress/runner/cypress_runner.js:159630:10)
    at Async.drainQueues (http://127.0.0.1:8080/__cypress/runner/cypress_runner.js:159504:14)]]></failure>
    </testcase>
  </testsuite>
</testsuites>